[ERROR] [2019-10-13 19:43:03,764] [views] [379] 其它错误 name 'data' is not defined
[ERROR] [2019-10-13 19:47:54,030] [views] [380] 其它错误 'dict' object has no attribute 'host'
[ERROR] [2019-10-13 19:53:56,059] [views] [380] 其它错误 'dict' object has no attribute 'host'
[ERROR] [2019-10-13 19:54:48,999] [views] [380] 其它错误 'dict' object has no attribute 'host'
[ERROR] [2019-10-13 19:55:02,074] [log] [228] Internal Server Error: /vmstate/
Traceback (most recent call last):
  File "C:\Users\secondBrother\.virtualenvs\py\lib\site-packages\django\core\handlers\exception.py", line 34, in inner
    response = get_response(request)
  File "C:\Users\secondBrother\.virtualenvs\py\lib\site-packages\django\core\handlers\base.py", line 126, in _get_response
    response = self.process_exception_by_middleware(e, request)
  File "C:\Users\secondBrother\.virtualenvs\py\lib\site-packages\django\core\handlers\base.py", line 124, in _get_response
    response = wrapped_callback(request, *callback_args, **callback_kwargs)
  File "C:\Users\secondBrother\.virtualenvs\py\lib\site-packages\django\views\generic\base.py", line 68, in view
    return self.dispatch(request, *args, **kwargs)
  File "C:\Users\secondBrother\.virtualenvs\py\lib\site-packages\django\views\generic\base.py", line 88, in dispatch
    return handler(request, *args, **kwargs)
  File "D:\project\yeslab-booking-systerm\backend\experiments\views.py", line 381, in post
    raise e
  File "D:\project\yeslab-booking-systerm\backend\experiments\views.py", line 368, in post
    vm = VMS(host=rack.rack_host,port=rack.rack_port,user=rack.rack_user,pwd=rack.rack_pwd)
  File "D:\project\yeslab-booking-systerm\backend\utils\snapshot.py", line 11, in __new__
    if obj.host == kwargs.host:
AttributeError: 'dict' object has no attribute 'host'
[ERROR] [2019-10-13 19:55:02,079] [basehttp] [136] "POST /vmstate/ HTTP/1.1" 500 92818
[ERROR] [2019-10-15 16:04:19,994] [log] [228] Internal Server Error: /api/userinfo/1
Traceback (most recent call last):
  File "C:\Users\secondBrother\.virtualenvs\py\lib\site-packages\django\core\handlers\exception.py", line 34, in inner
    response = get_response(request)
  File "C:\Users\secondBrother\.virtualenvs\py\lib\site-packages\django\core\handlers\base.py", line 126, in _get_response
    response = self.process_exception_by_middleware(e, request)
  File "C:\Users\secondBrother\.virtualenvs\py\lib\site-packages\django\core\handlers\base.py", line 124, in _get_response
    response = wrapped_callback(request, *callback_args, **callback_kwargs)
  File "C:\Users\secondBrother\.virtualenvs\py\lib\site-packages\django\views\generic\base.py", line 68, in view
    return self.dispatch(request, *args, **kwargs)
  File "C:\Users\secondBrother\.virtualenvs\py\lib\site-packages\django\views\generic\base.py", line 88, in dispatch
    return handler(request, *args, **kwargs)
  File "D:\project\yeslab-booking-systerm\backend\users\views.py", line 216, in post
    name = dataList.get('name')
AttributeError: 'NoneType' object has no attribute 'get'
[ERROR] [2019-10-15 16:04:19,997] [basehttp] [136] "POST /api/userinfo/1 HTTP/1.1" 500 84628
[ERROR] [2019-10-15 16:04:25,058] [log] [228] Internal Server Error: /api/userinfo/1
Traceback (most recent call last):
  File "C:\Users\secondBrother\.virtualenvs\py\lib\site-packages\django\core\handlers\exception.py", line 34, in inner
    response = get_response(request)
  File "C:\Users\secondBrother\.virtualenvs\py\lib\site-packages\django\core\handlers\base.py", line 126, in _get_response
    response = self.process_exception_by_middleware(e, request)
  File "C:\Users\secondBrother\.virtualenvs\py\lib\site-packages\django\core\handlers\base.py", line 124, in _get_response
    response = wrapped_callback(request, *callback_args, **callback_kwargs)
  File "C:\Users\secondBrother\.virtualenvs\py\lib\site-packages\django\views\generic\base.py", line 68, in view
    return self.dispatch(request, *args, **kwargs)
  File "C:\Users\secondBrother\.virtualenvs\py\lib\site-packages\django\views\generic\base.py", line 88, in dispatch
    return handler(request, *args, **kwargs)
  File "D:\project\yeslab-booking-systerm\backend\users\views.py", line 216, in post
    name = dataList.get('name')
AttributeError: 'NoneType' object has no attribute 'get'
[ERROR] [2019-10-15 16:04:25,098] [basehttp] [136] "POST /api/userinfo/1 HTTP/1.1" 500 84628
[ERROR] [2019-10-16 09:26:46,120] [basehttp] [136] "GET /api/myreservations/1/ HTTP/1.1" 500 59
[ERROR] [2019-10-16 11:05:37,952] [log] [228] Internal Server Error: /api/interview_msg/
Traceback (most recent call last):
  File "C:\Users\secondBrother\.virtualenvs\py\lib\site-packages\django\core\handlers\exception.py", line 34, in inner
    response = get_response(request)
  File "C:\Users\secondBrother\.virtualenvs\py\lib\site-packages\django\core\handlers\base.py", line 137, in _get_response
    "returned None instead." % (callback.__module__, view_name)
ValueError: The view infos.views.Interview didn't return an HttpResponse object. It returned None instead.
[ERROR] [2019-10-16 11:05:37,955] [basehttp] [136] "GET /api/interview_msg/?date=2019-10-16 HTTP/1.1" 500 66046
[ERROR] [2019-10-16 11:05:43,910] [log] [228] Internal Server Error: /api/interview_msg/
Traceback (most recent call last):
  File "C:\Users\secondBrother\.virtualenvs\py\lib\site-packages\django\core\handlers\exception.py", line 34, in inner
    response = get_response(request)
  File "C:\Users\secondBrother\.virtualenvs\py\lib\site-packages\django\core\handlers\base.py", line 137, in _get_response
    "returned None instead." % (callback.__module__, view_name)
ValueError: The view infos.views.Interview didn't return an HttpResponse object. It returned None instead.
[ERROR] [2019-10-16 11:05:43,913] [basehttp] [136] "GET /api/interview_msg/?date=2019-10-16 HTTP/1.1" 500 66046
[ERROR] [2019-10-16 11:05:46,725] [log] [228] Internal Server Error: /api/interview_msg/
Traceback (most recent call last):
  File "C:\Users\secondBrother\.virtualenvs\py\lib\site-packages\django\core\handlers\exception.py", line 34, in inner
    response = get_response(request)
  File "C:\Users\secondBrother\.virtualenvs\py\lib\site-packages\django\core\handlers\base.py", line 137, in _get_response
    "returned None instead." % (callback.__module__, view_name)
ValueError: The view infos.views.Interview didn't return an HttpResponse object. It returned None instead.
[ERROR] [2019-10-16 11:05:46,727] [basehttp] [136] "GET /api/interview_msg/?date=2019-10-16 HTTP/1.1" 500 66046
[ERROR] [2019-10-16 11:07:28,632] [log] [228] Internal Server Error: /api/register/
Traceback (most recent call last):
  File "C:\Users\secondBrother\.virtualenvs\py\lib\site-packages\django\db\backends\utils.py", line 85, in _execute
    return self.cursor.execute(sql, params)
  File "C:\Users\secondBrother\.virtualenvs\py\lib\site-packages\django\db\backends\mysql\base.py", line 71, in execute
    return self.cursor.execute(query, args)
  File "C:\Users\secondBrother\.virtualenvs\py\lib\site-packages\pymysql\cursors.py", line 170, in execute
    result = self._query(query)
  File "C:\Users\secondBrother\.virtualenvs\py\lib\site-packages\pymysql\cursors.py", line 328, in _query
    conn.query(q)
  File "C:\Users\secondBrother\.virtualenvs\py\lib\site-packages\pymysql\connections.py", line 517, in query
    self._affected_rows = self._read_query_result(unbuffered=unbuffered)
  File "C:\Users\secondBrother\.virtualenvs\py\lib\site-packages\pymysql\connections.py", line 732, in _read_query_result
    result.read()
  File "C:\Users\secondBrother\.virtualenvs\py\lib\site-packages\pymysql\connections.py", line 1075, in read
    first_packet = self.connection._read_packet()
  File "C:\Users\secondBrother\.virtualenvs\py\lib\site-packages\pymysql\connections.py", line 684, in _read_packet
    packet.check_error()
  File "C:\Users\secondBrother\.virtualenvs\py\lib\site-packages\pymysql\protocol.py", line 220, in check_error
    err.raise_mysql_exception(self._data)
  File "C:\Users\secondBrother\.virtualenvs\py\lib\site-packages\pymysql\err.py", line 109, in raise_mysql_exception
    raise errorclass(errno, errval)
pymysql.err.DataError: (1406, "Data too long for column 'password' at row 1")

The above exception was the direct cause of the following exception:

Traceback (most recent call last):
  File "C:\Users\secondBrother\.virtualenvs\py\lib\site-packages\django\core\handlers\exception.py", line 34, in inner
    response = get_response(request)
  File "C:\Users\secondBrother\.virtualenvs\py\lib\site-packages\django\core\handlers\base.py", line 126, in _get_response
    response = self.process_exception_by_middleware(e, request)
  File "C:\Users\secondBrother\.virtualenvs\py\lib\site-packages\django\core\handlers\base.py", line 124, in _get_response
    response = wrapped_callback(request, *callback_args, **callback_kwargs)
  File "C:\Users\secondBrother\.virtualenvs\py\lib\site-packages\django\views\generic\base.py", line 68, in view
    return self.dispatch(request, *args, **kwargs)
  File "C:\Users\secondBrother\.virtualenvs\py\lib\site-packages\django\views\generic\base.py", line 88, in dispatch
    return handler(request, *args, **kwargs)
  File "D:\project\yeslab-booking-systerm\backend\users\views.py", line 66, in post
    user.save()
  File "C:\Users\secondBrother\.virtualenvs\py\lib\site-packages\django\db\models\base.py", line 718, in save
    force_update=force_update, update_fields=update_fields)
  File "C:\Users\secondBrother\.virtualenvs\py\lib\site-packages\django\db\models\base.py", line 748, in save_base
    updated = self._save_table(raw, cls, force_insert, force_update, using, update_fields)
  File "C:\Users\secondBrother\.virtualenvs\py\lib\site-packages\django\db\models\base.py", line 831, in _save_table
    result = self._do_insert(cls._base_manager, using, fields, update_pk, raw)
  File "C:\Users\secondBrother\.virtualenvs\py\lib\site-packages\django\db\models\base.py", line 869, in _do_insert
    using=using, raw=raw)
  File "C:\Users\secondBrother\.virtualenvs\py\lib\site-packages\django\db\models\manager.py", line 82, in manager_method
    return getattr(self.get_queryset(), name)(*args, **kwargs)
  File "C:\Users\secondBrother\.virtualenvs\py\lib\site-packages\django\db\models\query.py", line 1136, in _insert
    return query.get_compiler(using=using).execute_sql(return_id)
  File "C:\Users\secondBrother\.virtualenvs\py\lib\site-packages\django\db\models\sql\compiler.py", line 1289, in execute_sql
    cursor.execute(sql, params)
  File "C:\Users\secondBrother\.virtualenvs\py\lib\site-packages\django\db\backends\utils.py", line 100, in execute
    return super().execute(sql, params)
  File "C:\Users\secondBrother\.virtualenvs\py\lib\site-packages\django\db\backends\utils.py", line 68, in execute
    return self._execute_with_wrappers(sql, params, many=False, executor=self._execute)
  File "C:\Users\secondBrother\.virtualenvs\py\lib\site-packages\django\db\backends\utils.py", line 77, in _execute_with_wrappers
    return executor(sql, params, many, context)
  File "C:\Users\secondBrother\.virtualenvs\py\lib\site-packages\django\db\backends\utils.py", line 85, in _execute
    return self.cursor.execute(sql, params)
  File "C:\Users\secondBrother\.virtualenvs\py\lib\site-packages\django\db\utils.py", line 89, in __exit__
    raise dj_exc_value.with_traceback(traceback) from exc_value
  File "C:\Users\secondBrother\.virtualenvs\py\lib\site-packages\django\db\backends\utils.py", line 85, in _execute
    return self.cursor.execute(sql, params)
  File "C:\Users\secondBrother\.virtualenvs\py\lib\site-packages\django\db\backends\mysql\base.py", line 71, in execute
    return self.cursor.execute(query, args)
  File "C:\Users\secondBrother\.virtualenvs\py\lib\site-packages\pymysql\cursors.py", line 170, in execute
    result = self._query(query)
  File "C:\Users\secondBrother\.virtualenvs\py\lib\site-packages\pymysql\cursors.py", line 328, in _query
    conn.query(q)
  File "C:\Users\secondBrother\.virtualenvs\py\lib\site-packages\pymysql\connections.py", line 517, in query
    self._affected_rows = self._read_query_result(unbuffered=unbuffered)
  File "C:\Users\secondBrother\.virtualenvs\py\lib\site-packages\pymysql\connections.py", line 732, in _read_query_result
    result.read()
  File "C:\Users\secondBrother\.virtualenvs\py\lib\site-packages\pymysql\connections.py", line 1075, in read
    first_packet = self.connection._read_packet()
  File "C:\Users\secondBrother\.virtualenvs\py\lib\site-packages\pymysql\connections.py", line 684, in _read_packet
    packet.check_error()
  File "C:\Users\secondBrother\.virtualenvs\py\lib\site-packages\pymysql\protocol.py", line 220, in check_error
    err.raise_mysql_exception(self._data)
  File "C:\Users\secondBrother\.virtualenvs\py\lib\site-packages\pymysql\err.py", line 109, in raise_mysql_exception
    raise errorclass(errno, errval)
django.db.utils.DataError: (1406, "Data too long for column 'password' at row 1")
[ERROR] [2019-10-16 11:07:28,656] [basehttp] [136] "POST /api/register/ HTTP/1.1" 500 231570
[ERROR] [2019-10-16 11:48:25,462] [log] [228] Internal Server Error: /api/login/
Traceback (most recent call last):
  File "D:\project\yeslab-booking-systerm\backend\users\views.py", line 108, in post
    user = UserInfo.objects.get(username=username,password=password,)
AttributeError: type object 'UserInfo' has no attribute 'objects'

During handling of the above exception, another exception occurred:

Traceback (most recent call last):
  File "C:\Users\secondBrother\.virtualenvs\py\lib\site-packages\django\core\handlers\exception.py", line 34, in inner
    response = get_response(request)
  File "C:\Users\secondBrother\.virtualenvs\py\lib\site-packages\django\core\handlers\base.py", line 126, in _get_response
    response = self.process_exception_by_middleware(e, request)
  File "C:\Users\secondBrother\.virtualenvs\py\lib\site-packages\django\core\handlers\base.py", line 124, in _get_response
    response = wrapped_callback(request, *callback_args, **callback_kwargs)
  File "C:\Users\secondBrother\.virtualenvs\py\lib\site-packages\django\views\decorators\csrf.py", line 54, in wrapped_view
    return view_func(*args, **kwargs)
  File "C:\Users\secondBrother\.virtualenvs\py\lib\site-packages\django\views\generic\base.py", line 68, in view
    return self.dispatch(request, *args, **kwargs)
  File "C:\Users\secondBrother\.virtualenvs\py\lib\site-packages\django\views\generic\base.py", line 88, in dispatch
    return handler(request, *args, **kwargs)
  File "D:\project\yeslab-booking-systerm\backend\users\views.py", line 109, in post
    except UserInfo.DoesNotExist as e:
AttributeError: type object 'UserInfo' has no attribute 'DoesNotExist'
[ERROR] [2019-10-16 11:48:25,465] [basehttp] [136] "POST /api/login/ HTTP/1.1" 500 93867
[ERROR] [2019-10-16 11:53:40,944] [log] [228] Internal Server Error: /api/userinfo/1
Traceback (most recent call last):
  File "C:\Users\secondBrother\.virtualenvs\py\lib\site-packages\django\core\handlers\exception.py", line 34, in inner
    response = get_response(request)
  File "C:\Users\secondBrother\.virtualenvs\py\lib\site-packages\django\core\handlers\base.py", line 126, in _get_response
    response = self.process_exception_by_middleware(e, request)
  File "C:\Users\secondBrother\.virtualenvs\py\lib\site-packages\django\core\handlers\base.py", line 124, in _get_response
    response = wrapped_callback(request, *callback_args, **callback_kwargs)
  File "C:\Users\secondBrother\.virtualenvs\py\lib\site-packages\django\views\generic\base.py", line 68, in view
    return self.dispatch(request, *args, **kwargs)
  File "C:\Users\secondBrother\.virtualenvs\py\lib\site-packages\django\views\generic\base.py", line 88, in dispatch
    return handler(request, *args, **kwargs)
  File "D:\project\yeslab-booking-systerm\backend\users\views.py", line 299, in get
    user = UserInfos.objects.get(id=user_id)
AttributeError: type object 'UserInfos' has no attribute 'objects'
[ERROR] [2019-10-16 11:53:40,947] [basehttp] [136] "GET /api/userinfo/1 HTTP/1.1" 500 84098
[ERROR] [2019-10-16 11:54:25,294] [log] [228] Internal Server Error: /api/userinfo/2
Traceback (most recent call last):
  File "C:\Users\secondBrother\.virtualenvs\py\lib\site-packages\django\core\handlers\exception.py", line 34, in inner
    response = get_response(request)
  File "C:\Users\secondBrother\.virtualenvs\py\lib\site-packages\django\core\handlers\base.py", line 126, in _get_response
    response = self.process_exception_by_middleware(e, request)
  File "C:\Users\secondBrother\.virtualenvs\py\lib\site-packages\django\core\handlers\base.py", line 124, in _get_response
    response = wrapped_callback(request, *callback_args, **callback_kwargs)
  File "C:\Users\secondBrother\.virtualenvs\py\lib\site-packages\django\views\generic\base.py", line 68, in view
    return self.dispatch(request, *args, **kwargs)
  File "C:\Users\secondBrother\.virtualenvs\py\lib\site-packages\django\views\generic\base.py", line 88, in dispatch
    return handler(request, *args, **kwargs)
  File "D:\project\yeslab-booking-systerm\backend\users\views.py", line 299, in get
    user = UserInfos.objects.get(id=user_id)
AttributeError: type object 'UserInfos' has no attribute 'objects'
[ERROR] [2019-10-16 11:54:25,298] [basehttp] [136] "GET /api/userinfo/2 HTTP/1.1" 500 84098
[ERROR] [2019-10-16 11:57:28,042] [log] [228] Internal Server Error: /api/userinfo/1
Traceback (most recent call last):
  File "C:\Users\secondBrother\.virtualenvs\py\lib\site-packages\django\core\handlers\exception.py", line 34, in inner
    response = get_response(request)
  File "C:\Users\secondBrother\.virtualenvs\py\lib\site-packages\django\core\handlers\base.py", line 126, in _get_response
    response = self.process_exception_by_middleware(e, request)
  File "C:\Users\secondBrother\.virtualenvs\py\lib\site-packages\django\core\handlers\base.py", line 124, in _get_response
    response = wrapped_callback(request, *callback_args, **callback_kwargs)
  File "C:\Users\secondBrother\.virtualenvs\py\lib\site-packages\django\views\generic\base.py", line 68, in view
    return self.dispatch(request, *args, **kwargs)
  File "C:\Users\secondBrother\.virtualenvs\py\lib\site-packages\django\views\generic\base.py", line 88, in dispatch
    return handler(request, *args, **kwargs)
  File "D:\project\yeslab-booking-systerm\backend\users\views.py", line 299, in get
    user = UserInfos.objects.get(id=user_id)
AttributeError: type object 'UserInfos' has no attribute 'objects'
[ERROR] [2019-10-16 11:57:28,045] [basehttp] [136] "GET /api/userinfo/1 HTTP/1.1" 500 84098
[ERROR] [2019-10-16 11:58:00,097] [log] [228] Internal Server Error: /api/userinfo/1
Traceback (most recent call last):
  File "C:\Users\secondBrother\.virtualenvs\py\lib\site-packages\django\core\handlers\exception.py", line 34, in inner
    response = get_response(request)
  File "C:\Users\secondBrother\.virtualenvs\py\lib\site-packages\django\core\handlers\base.py", line 126, in _get_response
    response = self.process_exception_by_middleware(e, request)
  File "C:\Users\secondBrother\.virtualenvs\py\lib\site-packages\django\core\handlers\base.py", line 124, in _get_response
    response = wrapped_callback(request, *callback_args, **callback_kwargs)
  File "C:\Users\secondBrother\.virtualenvs\py\lib\site-packages\django\views\generic\base.py", line 68, in view
    return self.dispatch(request, *args, **kwargs)
  File "C:\Users\secondBrother\.virtualenvs\py\lib\site-packages\django\views\generic\base.py", line 88, in dispatch
    return handler(request, *args, **kwargs)
  File "D:\project\yeslab-booking-systerm\backend\users\views.py", line 299, in get
    user = UserInfos.objects.get(id=user_id)
AttributeError: type object 'UserInfos' has no attribute 'objects'
[ERROR] [2019-10-16 11:58:00,100] [basehttp] [136] "GET /api/userinfo/1 HTTP/1.1" 500 84098
[ERROR] [2019-10-16 12:03:48,217] [log] [228] Internal Server Error: /api/userinfo/1
Traceback (most recent call last):
  File "C:\Users\secondBrother\.virtualenvs\py\lib\site-packages\django\core\handlers\exception.py", line 34, in inner
    response = get_response(request)
  File "C:\Users\secondBrother\.virtualenvs\py\lib\site-packages\django\core\handlers\base.py", line 126, in _get_response
    response = self.process_exception_by_middleware(e, request)
  File "C:\Users\secondBrother\.virtualenvs\py\lib\site-packages\django\core\handlers\base.py", line 124, in _get_response
    response = wrapped_callback(request, *callback_args, **callback_kwargs)
  File "C:\Users\secondBrother\.virtualenvs\py\lib\site-packages\django\views\generic\base.py", line 68, in view
    return self.dispatch(request, *args, **kwargs)
  File "C:\Users\secondBrother\.virtualenvs\py\lib\site-packages\django\views\generic\base.py", line 88, in dispatch
    return handler(request, *args, **kwargs)
  File "D:\project\yeslab-booking-systerm\backend\users\views.py", line 299, in get
    user = UserInfos.objects.get(id=user_id)
AttributeError: type object 'UserInfos' has no attribute 'objects'
[ERROR] [2019-10-16 12:03:48,219] [basehttp] [136] "GET /api/userinfo/1 HTTP/1.1" 500 84098
[ERROR] [2019-10-16 12:07:39,500] [log] [228] Internal Server Error: /api/userinfo/1
Traceback (most recent call last):
  File "C:\Users\secondBrother\.virtualenvs\py\lib\site-packages\django\core\handlers\exception.py", line 34, in inner
    response = get_response(request)
  File "C:\Users\secondBrother\.virtualenvs\py\lib\site-packages\django\core\handlers\base.py", line 126, in _get_response
    response = self.process_exception_by_middleware(e, request)
  File "C:\Users\secondBrother\.virtualenvs\py\lib\site-packages\django\core\handlers\base.py", line 124, in _get_response
    response = wrapped_callback(request, *callback_args, **callback_kwargs)
  File "C:\Users\secondBrother\.virtualenvs\py\lib\site-packages\django\views\generic\base.py", line 68, in view
    return self.dispatch(request, *args, **kwargs)
  File "C:\Users\secondBrother\.virtualenvs\py\lib\site-packages\django\views\generic\base.py", line 88, in dispatch
    return handler(request, *args, **kwargs)
  File "D:\project\yeslab-booking-systerm\backend\users\views.py", line 299, in get
    user = UserInfos.objects.get(id=user_id)
AttributeError: type object 'UserInfos' has no attribute 'objects'
[ERROR] [2019-10-16 12:07:39,504] [basehttp] [136] "GET /api/userinfo/1 HTTP/1.1" 500 84098
[ERROR] [2019-10-16 14:58:18,017] [views] [245] 邮件发送失败：Connection unexpectedly closed
[ERROR] [2019-10-16 15:05:10,798] [log] [228] Internal Server Error: /xadmin/users/userinfo/1/update/
Traceback (most recent call last):
  File "C:\Users\secondBrother\.virtualenvs\py\lib\site-packages\django\db\backends\utils.py", line 85, in _execute
    return self.cursor.execute(sql, params)
  File "C:\Users\secondBrother\.virtualenvs\py\lib\site-packages\django\db\backends\mysql\base.py", line 71, in execute
    return self.cursor.execute(query, args)
  File "C:\Users\secondBrother\.virtualenvs\py\lib\site-packages\pymysql\cursors.py", line 170, in execute
    result = self._query(query)
  File "C:\Users\secondBrother\.virtualenvs\py\lib\site-packages\pymysql\cursors.py", line 328, in _query
    conn.query(q)
  File "C:\Users\secondBrother\.virtualenvs\py\lib\site-packages\pymysql\connections.py", line 517, in query
    self._affected_rows = self._read_query_result(unbuffered=unbuffered)
  File "C:\Users\secondBrother\.virtualenvs\py\lib\site-packages\pymysql\connections.py", line 732, in _read_query_result
    result.read()
  File "C:\Users\secondBrother\.virtualenvs\py\lib\site-packages\pymysql\connections.py", line 1075, in read
    first_packet = self.connection._read_packet()
  File "C:\Users\secondBrother\.virtualenvs\py\lib\site-packages\pymysql\connections.py", line 684, in _read_packet
    packet.check_error()
  File "C:\Users\secondBrother\.virtualenvs\py\lib\site-packages\pymysql\protocol.py", line 220, in check_error
    err.raise_mysql_exception(self._data)
  File "C:\Users\secondBrother\.virtualenvs\py\lib\site-packages\pymysql\err.py", line 109, in raise_mysql_exception
    raise errorclass(errno, errval)
pymysql.err.DataError: (1406, "Data too long for column 'password' at row 1")

The above exception was the direct cause of the following exception:

Traceback (most recent call last):
  File "C:\Users\secondBrother\.virtualenvs\py\lib\site-packages\django\core\handlers\exception.py", line 34, in inner
    response = get_response(request)
  File "C:\Users\secondBrother\.virtualenvs\py\lib\site-packages\django\core\handlers\base.py", line 126, in _get_response
    response = self.process_exception_by_middleware(e, request)
  File "C:\Users\secondBrother\.virtualenvs\py\lib\site-packages\django\core\handlers\base.py", line 124, in _get_response
    response = wrapped_callback(request, *callback_args, **callback_kwargs)
  File "D:\project\yeslab-booking-systerm\backend\xadmin\sites.py", line 300, in wrapper
    return self.admin_view(view, cacheable)(*args, **kwargs)
  File "C:\Users\secondBrother\.virtualenvs\py\lib\site-packages\django\views\decorators\cache.py", line 44, in _wrapped_view_func
    response = view_func(request, *args, **kwargs)
  File "D:\project\yeslab-booking-systerm\backend\xadmin\sites.py", line 208, in inner
    return view(request, *args, **kwargs)
  File "D:\project\yeslab-booking-systerm\backend\xadmin\views\base.py", line 282, in view
    return handler(request, *args, **kwargs)
  File "D:\project\yeslab-booking-systerm\backend\xadmin\views\edit.py", line 512, in post
    return super(UpdateAdminView, self).post(request, *args, **kwargs)
  File "C:\Users\secondBrother\.virtualenvs\py\lib\site-packages\django\utils\decorators.py", line 45, in _wrapper
    return bound_method(*args, **kwargs)
  File "C:\Users\secondBrother\.virtualenvs\py\lib\site-packages\django\utils\decorators.py", line 142, in _wrapped_view
    response = view_func(request, *args, **kwargs)
  File "C:\Python36\lib\contextlib.py", line 52, in inner
    return func(*args, **kwds)
  File "D:\project\yeslab-booking-systerm\backend\xadmin\views\base.py", line 80, in method
    return filter_chain(filters, len(filters) - 1, _inner_method, *args, **kwargs)
  File "D:\project\yeslab-booking-systerm\backend\xadmin\views\base.py", line 49, in filter_chain
    return func()
  File "D:\project\yeslab-booking-systerm\backend\xadmin\views\base.py", line 74, in _inner_method
    return func(self, *args, **kwargs)
  File "D:\project\yeslab-booking-systerm\backend\xadmin\views\edit.py", line 292, in post
    self.save_models()
  File "D:\project\yeslab-booking-systerm\backend\xadmin\views\base.py", line 80, in method
    return filter_chain(filters, len(filters) - 1, _inner_method, *args, **kwargs)
  File "D:\project\yeslab-booking-systerm\backend\xadmin\views\base.py", line 49, in filter_chain
    return func()
  File "D:\project\yeslab-booking-systerm\backend\xadmin\views\base.py", line 74, in _inner_method
    return func(self, *args, **kwargs)
  File "D:\project\yeslab-booking-systerm\backend\xadmin\views\edit.py", line 267, in save_models
    self.new_obj.save()
  File "C:\Users\secondBrother\.virtualenvs\py\lib\site-packages\django\db\models\base.py", line 718, in save
    force_update=force_update, update_fields=update_fields)
  File "C:\Users\secondBrother\.virtualenvs\py\lib\site-packages\django\db\models\base.py", line 748, in save_base
    updated = self._save_table(raw, cls, force_insert, force_update, using, update_fields)
  File "C:\Users\secondBrother\.virtualenvs\py\lib\site-packages\django\db\models\base.py", line 812, in _save_table
    forced_update)
  File "C:\Users\secondBrother\.virtualenvs\py\lib\site-packages\django\db\models\base.py", line 861, in _do_update
    return filtered._update(values) > 0
  File "C:\Users\secondBrother\.virtualenvs\py\lib\site-packages\django\db\models\query.py", line 712, in _update
    return query.get_compiler(self.db).execute_sql(CURSOR)
  File "C:\Users\secondBrother\.virtualenvs\py\lib\site-packages\django\db\models\sql\compiler.py", line 1383, in execute_sql
    cursor = super().execute_sql(result_type)
  File "C:\Users\secondBrother\.virtualenvs\py\lib\site-packages\django\db\models\sql\compiler.py", line 1065, in execute_sql
    cursor.execute(sql, params)
  File "C:\Users\secondBrother\.virtualenvs\py\lib\site-packages\django\db\backends\utils.py", line 100, in execute
    return super().execute(sql, params)
  File "C:\Users\secondBrother\.virtualenvs\py\lib\site-packages\django\db\backends\utils.py", line 68, in execute
    return self._execute_with_wrappers(sql, params, many=False, executor=self._execute)
  File "C:\Users\secondBrother\.virtualenvs\py\lib\site-packages\django\db\backends\utils.py", line 77, in _execute_with_wrappers
    return executor(sql, params, many, context)
  File "C:\Users\secondBrother\.virtualenvs\py\lib\site-packages\django\db\backends\utils.py", line 85, in _execute
    return self.cursor.execute(sql, params)
  File "C:\Users\secondBrother\.virtualenvs\py\lib\site-packages\django\db\utils.py", line 89, in __exit__
    raise dj_exc_value.with_traceback(traceback) from exc_value
  File "C:\Users\secondBrother\.virtualenvs\py\lib\site-packages\django\db\backends\utils.py", line 85, in _execute
    return self.cursor.execute(sql, params)
  File "C:\Users\secondBrother\.virtualenvs\py\lib\site-packages\django\db\backends\mysql\base.py", line 71, in execute
    return self.cursor.execute(query, args)
  File "C:\Users\secondBrother\.virtualenvs\py\lib\site-packages\pymysql\cursors.py", line 170, in execute
    result = self._query(query)
  File "C:\Users\secondBrother\.virtualenvs\py\lib\site-packages\pymysql\cursors.py", line 328, in _query
    conn.query(q)
  File "C:\Users\secondBrother\.virtualenvs\py\lib\site-packages\pymysql\connections.py", line 517, in query
    self._affected_rows = self._read_query_result(unbuffered=unbuffered)
  File "C:\Users\secondBrother\.virtualenvs\py\lib\site-packages\pymysql\connections.py", line 732, in _read_query_result
    result.read()
  File "C:\Users\secondBrother\.virtualenvs\py\lib\site-packages\pymysql\connections.py", line 1075, in read
    first_packet = self.connection._read_packet()
  File "C:\Users\secondBrother\.virtualenvs\py\lib\site-packages\pymysql\connections.py", line 684, in _read_packet
    packet.check_error()
  File "C:\Users\secondBrother\.virtualenvs\py\lib\site-packages\pymysql\protocol.py", line 220, in check_error
    err.raise_mysql_exception(self._data)
  File "C:\Users\secondBrother\.virtualenvs\py\lib\site-packages\pymysql\err.py", line 109, in raise_mysql_exception
    raise errorclass(errno, errval)
django.db.utils.DataError: (1406, "Data too long for column 'password' at row 1")
[ERROR] [2019-10-16 15:05:10,807] [basehttp] [136] "POST /xadmin/users/userinfo/1/update/ HTTP/1.1" 500 293383
[ERROR] [2019-10-16 15:06:32,835] [log] [228] Internal Server Error: /api/userinfo/1
Traceback (most recent call last):
  File "C:\Users\secondBrother\.virtualenvs\py\lib\site-packages\django\core\handlers\exception.py", line 34, in inner
    response = get_response(request)
  File "C:\Users\secondBrother\.virtualenvs\py\lib\site-packages\django\core\handlers\base.py", line 126, in _get_response
    response = self.process_exception_by_middleware(e, request)
  File "C:\Users\secondBrother\.virtualenvs\py\lib\site-packages\django\core\handlers\base.py", line 124, in _get_response
    response = wrapped_callback(request, *callback_args, **callback_kwargs)
  File "C:\Users\secondBrother\.virtualenvs\py\lib\site-packages\django\views\generic\base.py", line 68, in view
    return self.dispatch(request, *args, **kwargs)
  File "C:\Users\secondBrother\.virtualenvs\py\lib\site-packages\django\views\generic\base.py", line 88, in dispatch
    return handler(request, *args, **kwargs)
  File "D:\project\yeslab-booking-systerm\backend\users\views.py", line 292, in get
    user = UserInfos.objects.get(id=user_id)
AttributeError: type object 'UserInfos' has no attribute 'objects'
[ERROR] [2019-10-16 15:06:32,838] [basehttp] [136] "GET /api/userinfo/1 HTTP/1.1" 500 84073
[ERROR] [2019-10-16 15:06:41,658] [log] [228] Internal Server Error: /api/userinfo/1
Traceback (most recent call last):
  File "C:\Users\secondBrother\.virtualenvs\py\lib\site-packages\django\core\handlers\exception.py", line 34, in inner
    response = get_response(request)
  File "C:\Users\secondBrother\.virtualenvs\py\lib\site-packages\django\core\handlers\base.py", line 126, in _get_response
    response = self.process_exception_by_middleware(e, request)
  File "C:\Users\secondBrother\.virtualenvs\py\lib\site-packages\django\core\handlers\base.py", line 124, in _get_response
    response = wrapped_callback(request, *callback_args, **callback_kwargs)
  File "C:\Users\secondBrother\.virtualenvs\py\lib\site-packages\django\views\generic\base.py", line 68, in view
    return self.dispatch(request, *args, **kwargs)
  File "C:\Users\secondBrother\.virtualenvs\py\lib\site-packages\django\views\generic\base.py", line 88, in dispatch
    return handler(request, *args, **kwargs)
  File "D:\project\yeslab-booking-systerm\backend\users\views.py", line 292, in get
    user = UserInfos.objects.get(id=user_id)
AttributeError: type object 'UserInfos' has no attribute 'objects'
[ERROR] [2019-10-16 15:06:41,706] [basehttp] [136] "GET /api/userinfo/1 HTTP/1.1" 500 84073
[ERROR] [2019-10-16 15:11:44,075] [log] [228] Internal Server Error: /api/userinfo/1
Traceback (most recent call last):
  File "C:\Users\secondBrother\.virtualenvs\py\lib\site-packages\django\core\handlers\exception.py", line 34, in inner
    response = get_response(request)
  File "C:\Users\secondBrother\.virtualenvs\py\lib\site-packages\django\core\handlers\base.py", line 126, in _get_response
    response = self.process_exception_by_middleware(e, request)
  File "C:\Users\secondBrother\.virtualenvs\py\lib\site-packages\django\core\handlers\base.py", line 124, in _get_response
    response = wrapped_callback(request, *callback_args, **callback_kwargs)
  File "C:\Users\secondBrother\.virtualenvs\py\lib\site-packages\django\views\generic\base.py", line 68, in view
    return self.dispatch(request, *args, **kwargs)
  File "C:\Users\secondBrother\.virtualenvs\py\lib\site-packages\django\utils\decorators.py", line 45, in _wrapper
    return bound_method(*args, **kwargs)
  File "D:\project\yeslab-booking-systerm\backend\users\views.py", line 30, in inner
    return func(request,*args,**kwargs)
  File "C:\Users\secondBrother\.virtualenvs\py\lib\site-packages\django\views\generic\base.py", line 88, in dispatch
    return handler(request, *args, **kwargs)
  File "D:\project\yeslab-booking-systerm\backend\users\views.py", line 171, in get
    user = UserInfos.objects.get(id=user_id)
AttributeError: type object 'UserInfos' has no attribute 'objects'
[ERROR] [2019-10-16 15:11:44,080] [basehttp] [136] "GET /api/userinfo/1 HTTP/1.1" 500 93979
[ERROR] [2019-10-16 15:23:52,016] [views] [26] 'HTTP_AUTHORIZATION'
[ERROR] [2019-10-16 15:26:12,324] [views] [215] 个人信息保存失败type object 'UserInfos' has no attribute 'objects'
[ERROR] [2019-10-16 16:02:52,458] [log] [228] Internal Server Error: /api/interview_msg/
Traceback (most recent call last):
  File "C:\Users\secondBrother\.virtualenvs\py\lib\site-packages\django\core\handlers\exception.py", line 34, in inner
    response = get_response(request)
  File "C:\Users\secondBrother\.virtualenvs\py\lib\site-packages\django\core\handlers\base.py", line 126, in _get_response
    response = self.process_exception_by_middleware(e, request)
  File "C:\Users\secondBrother\.virtualenvs\py\lib\site-packages\django\core\handlers\base.py", line 124, in _get_response
    response = wrapped_callback(request, *callback_args, **callback_kwargs)
  File "C:\Users\secondBrother\.virtualenvs\py\lib\site-packages\django\views\generic\base.py", line 68, in view
    return self.dispatch(request, *args, **kwargs)
  File "C:\Users\secondBrother\.virtualenvs\py\lib\site-packages\django\views\generic\base.py", line 88, in dispatch
    return handler(request, *args, **kwargs)
  File "D:\project\yeslab-booking-systerm\backend\infos\views.py", line 25, in get
    date = datetime.date(req_date)
TypeError: an integer is required (got type str)
[ERROR] [2019-10-16 16:02:52,502] [basehttp] [136] "GET /api/interview_msg/?date=2019-10-16 HTTP/1.1" 500 84504
[ERROR] [2019-10-16 16:02:55,879] [log] [228] Internal Server Error: /api/interview_msg/
Traceback (most recent call last):
  File "C:\Users\secondBrother\.virtualenvs\py\lib\site-packages\django\core\handlers\exception.py", line 34, in inner
    response = get_response(request)
  File "C:\Users\secondBrother\.virtualenvs\py\lib\site-packages\django\core\handlers\base.py", line 126, in _get_response
    response = self.process_exception_by_middleware(e, request)
  File "C:\Users\secondBrother\.virtualenvs\py\lib\site-packages\django\core\handlers\base.py", line 124, in _get_response
    response = wrapped_callback(request, *callback_args, **callback_kwargs)
  File "C:\Users\secondBrother\.virtualenvs\py\lib\site-packages\django\views\generic\base.py", line 68, in view
    return self.dispatch(request, *args, **kwargs)
  File "C:\Users\secondBrother\.virtualenvs\py\lib\site-packages\django\views\generic\base.py", line 88, in dispatch
    return handler(request, *args, **kwargs)
  File "D:\project\yeslab-booking-systerm\backend\infos\views.py", line 25, in get
    date = datetime.date(req_date)
TypeError: an integer is required (got type str)
[ERROR] [2019-10-16 16:02:55,882] [basehttp] [136] "GET /api/interview_msg/?date=2019-10-16 HTTP/1.1" 500 84504
[ERROR] [2019-10-16 16:04:42,891] [log] [228] Internal Server Error: /api/interview_msg/
Traceback (most recent call last):
  File "C:\Users\secondBrother\.virtualenvs\py\lib\site-packages\django\core\handlers\exception.py", line 34, in inner
    response = get_response(request)
  File "C:\Users\secondBrother\.virtualenvs\py\lib\site-packages\django\core\handlers\base.py", line 126, in _get_response
    response = self.process_exception_by_middleware(e, request)
  File "C:\Users\secondBrother\.virtualenvs\py\lib\site-packages\django\core\handlers\base.py", line 124, in _get_response
    response = wrapped_callback(request, *callback_args, **callback_kwargs)
  File "C:\Users\secondBrother\.virtualenvs\py\lib\site-packages\django\views\generic\base.py", line 68, in view
    return self.dispatch(request, *args, **kwargs)
  File "C:\Users\secondBrother\.virtualenvs\py\lib\site-packages\django\views\generic\base.py", line 88, in dispatch
    return handler(request, *args, **kwargs)
  File "D:\project\yeslab-booking-systerm\backend\infos\views.py", line 30, in get
    info = {"users":users,"tb_id":interviews.tb_id,"time_bucket": INTERVIEW_TIME_BUKET[interview.tb_id]}
AttributeError: 'QuerySet' object has no attribute 'tb_id'
[ERROR] [2019-10-16 16:04:42,894] [basehttp] [136] "GET /api/interview_msg/?date=2019-10-16 HTTP/1.1" 500 85984
[ERROR] [2019-10-16 16:05:50,597] [log] [228] Internal Server Error: /api/interview_msg/
Traceback (most recent call last):
  File "C:\Users\secondBrother\.virtualenvs\py\lib\site-packages\django\core\handlers\exception.py", line 34, in inner
    response = get_response(request)
  File "C:\Users\secondBrother\.virtualenvs\py\lib\site-packages\django\core\handlers\base.py", line 126, in _get_response
    response = self.process_exception_by_middleware(e, request)
  File "C:\Users\secondBrother\.virtualenvs\py\lib\site-packages\django\core\handlers\base.py", line 124, in _get_response
    response = wrapped_callback(request, *callback_args, **callback_kwargs)
  File "C:\Users\secondBrother\.virtualenvs\py\lib\site-packages\django\views\generic\base.py", line 68, in view
    return self.dispatch(request, *args, **kwargs)
  File "C:\Users\secondBrother\.virtualenvs\py\lib\site-packages\django\views\generic\base.py", line 88, in dispatch
    return handler(request, *args, **kwargs)
  File "D:\project\yeslab-booking-systerm\backend\infos\views.py", line 36, in get
    return JsonResponse(data, safe=False)
  File "C:\Users\secondBrother\.virtualenvs\py\lib\site-packages\django\http\response.py", line 558, in __init__
    data = json.dumps(data, cls=encoder, **json_dumps_params)
  File "C:\Python36\lib\json\__init__.py", line 238, in dumps
    **kw).encode(obj)
  File "C:\Python36\lib\json\encoder.py", line 199, in encode
    chunks = self.iterencode(o, _one_shot=True)
  File "C:\Python36\lib\json\encoder.py", line 257, in iterencode
    return _iterencode(o, 0)
  File "C:\Users\secondBrother\.virtualenvs\py\lib\site-packages\django\core\serializers\json.py", line 104, in default
    return super().default(o)
  File "C:\Python36\lib\json\encoder.py", line 180, in default
    o.__class__.__name__)
TypeError: Object of type 'QuerySet' is not JSON serializable
[ERROR] [2019-10-16 16:05:50,638] [basehttp] [136] "GET /api/interview_msg/?date=2019-10-16 HTTP/1.1" 500 116128
[ERROR] [2019-10-16 16:06:45,156] [log] [228] Internal Server Error: /api/interview_msg/
Traceback (most recent call last):
  File "C:\Users\secondBrother\.virtualenvs\py\lib\site-packages\django\core\handlers\exception.py", line 34, in inner
    response = get_response(request)
  File "C:\Users\secondBrother\.virtualenvs\py\lib\site-packages\django\core\handlers\base.py", line 126, in _get_response
    response = self.process_exception_by_middleware(e, request)
  File "C:\Users\secondBrother\.virtualenvs\py\lib\site-packages\django\core\handlers\base.py", line 124, in _get_response
    response = wrapped_callback(request, *callback_args, **callback_kwargs)
  File "C:\Users\secondBrother\.virtualenvs\py\lib\site-packages\django\views\generic\base.py", line 68, in view
    return self.dispatch(request, *args, **kwargs)
  File "C:\Users\secondBrother\.virtualenvs\py\lib\site-packages\django\views\generic\base.py", line 88, in dispatch
    return handler(request, *args, **kwargs)
  File "D:\project\yeslab-booking-systerm\backend\infos\views.py", line 36, in get
    return JsonResponse(data, safe=False)
  File "C:\Users\secondBrother\.virtualenvs\py\lib\site-packages\django\http\response.py", line 558, in __init__
    data = json.dumps(data, cls=encoder, **json_dumps_params)
  File "C:\Python36\lib\json\__init__.py", line 238, in dumps
    **kw).encode(obj)
  File "C:\Python36\lib\json\encoder.py", line 199, in encode
    chunks = self.iterencode(o, _one_shot=True)
  File "C:\Python36\lib\json\encoder.py", line 257, in iterencode
    return _iterencode(o, 0)
  File "C:\Users\secondBrother\.virtualenvs\py\lib\site-packages\django\core\serializers\json.py", line 104, in default
    return super().default(o)
  File "C:\Python36\lib\json\encoder.py", line 180, in default
    o.__class__.__name__)
TypeError: Object of type 'QuerySet' is not JSON serializable
[ERROR] [2019-10-16 16:06:45,158] [basehttp] [136] "GET /api/interview_msg/?date=2019-10-16 HTTP/1.1" 500 116147
[ERROR] [2019-10-16 16:07:22,928] [log] [228] Internal Server Error: /api/interview_msg/
Traceback (most recent call last):
  File "C:\Users\secondBrother\.virtualenvs\py\lib\site-packages\django\core\handlers\exception.py", line 34, in inner
    response = get_response(request)
  File "C:\Users\secondBrother\.virtualenvs\py\lib\site-packages\django\core\handlers\base.py", line 126, in _get_response
    response = self.process_exception_by_middleware(e, request)
  File "C:\Users\secondBrother\.virtualenvs\py\lib\site-packages\django\core\handlers\base.py", line 124, in _get_response
    response = wrapped_callback(request, *callback_args, **callback_kwargs)
  File "C:\Users\secondBrother\.virtualenvs\py\lib\site-packages\django\views\generic\base.py", line 68, in view
    return self.dispatch(request, *args, **kwargs)
  File "C:\Users\secondBrother\.virtualenvs\py\lib\site-packages\django\views\generic\base.py", line 88, in dispatch
    return handler(request, *args, **kwargs)
  File "D:\project\yeslab-booking-systerm\backend\infos\views.py", line 36, in get
    return JsonResponse(data, safe=False)
  File "C:\Users\secondBrother\.virtualenvs\py\lib\site-packages\django\http\response.py", line 558, in __init__
    data = json.dumps(data, cls=encoder, **json_dumps_params)
  File "C:\Python36\lib\json\__init__.py", line 238, in dumps
    **kw).encode(obj)
  File "C:\Python36\lib\json\encoder.py", line 199, in encode
    chunks = self.iterencode(o, _one_shot=True)
  File "C:\Python36\lib\json\encoder.py", line 257, in iterencode
    return _iterencode(o, 0)
  File "C:\Users\secondBrother\.virtualenvs\py\lib\site-packages\django\core\serializers\json.py", line 104, in default
    return super().default(o)
  File "C:\Python36\lib\json\encoder.py", line 180, in default
    o.__class__.__name__)
TypeError: Object of type 'QuerySet' is not JSON serializable
[ERROR] [2019-10-16 16:07:22,933] [basehttp] [136] "GET /api/interview_msg/?date=2019-10-16 HTTP/1.1" 500 116146
[ERROR] [2019-10-16 16:09:06,155] [log] [228] Internal Server Error: /api/interview_msg/
Traceback (most recent call last):
  File "C:\Users\secondBrother\.virtualenvs\py\lib\site-packages\django\core\handlers\exception.py", line 34, in inner
    response = get_response(request)
  File "C:\Users\secondBrother\.virtualenvs\py\lib\site-packages\django\core\handlers\base.py", line 126, in _get_response
    response = self.process_exception_by_middleware(e, request)
  File "C:\Users\secondBrother\.virtualenvs\py\lib\site-packages\django\core\handlers\base.py", line 124, in _get_response
    response = wrapped_callback(request, *callback_args, **callback_kwargs)
  File "C:\Users\secondBrother\.virtualenvs\py\lib\site-packages\django\views\generic\base.py", line 68, in view
    return self.dispatch(request, *args, **kwargs)
  File "C:\Users\secondBrother\.virtualenvs\py\lib\site-packages\django\views\generic\base.py", line 88, in dispatch
    return handler(request, *args, **kwargs)
  File "D:\project\yeslab-booking-systerm\backend\infos\views.py", line 36, in get
    return JsonResponse(data, safe=False)
  File "C:\Users\secondBrother\.virtualenvs\py\lib\site-packages\django\http\response.py", line 558, in __init__
    data = json.dumps(data, cls=encoder, **json_dumps_params)
  File "C:\Python36\lib\json\__init__.py", line 238, in dumps
    **kw).encode(obj)
  File "C:\Python36\lib\json\encoder.py", line 199, in encode
    chunks = self.iterencode(o, _one_shot=True)
  File "C:\Python36\lib\json\encoder.py", line 257, in iterencode
    return _iterencode(o, 0)
  File "C:\Users\secondBrother\.virtualenvs\py\lib\site-packages\django\core\serializers\json.py", line 104, in default
    return super().default(o)
  File "C:\Python36\lib\json\encoder.py", line 180, in default
    o.__class__.__name__)
TypeError: Object of type 'QuerySet' is not JSON serializable
[ERROR] [2019-10-16 16:09:06,159] [basehttp] [136] "GET /api/interview_msg/?date=2019-10-16 HTTP/1.1" 500 114552
[ERROR] [2019-10-16 16:24:36,328] [log] [228] Internal Server Error: /api/interview_msg/
Traceback (most recent call last):
  File "C:\Users\secondBrother\.virtualenvs\py\lib\site-packages\django\core\handlers\exception.py", line 34, in inner
    response = get_response(request)
  File "C:\Users\secondBrother\.virtualenvs\py\lib\site-packages\django\core\handlers\base.py", line 126, in _get_response
    response = self.process_exception_by_middleware(e, request)
  File "C:\Users\secondBrother\.virtualenvs\py\lib\site-packages\django\core\handlers\base.py", line 124, in _get_response
    response = wrapped_callback(request, *callback_args, **callback_kwargs)
  File "C:\Users\secondBrother\.virtualenvs\py\lib\site-packages\django\views\generic\base.py", line 68, in view
    return self.dispatch(request, *args, **kwargs)
  File "C:\Users\secondBrother\.virtualenvs\py\lib\site-packages\django\views\generic\base.py", line 88, in dispatch
    return handler(request, *args, **kwargs)
  File "D:\project\yeslab-booking-systerm\backend\infos\views.py", line 36, in get
    return JsonResponse(data.values(), safe=False)
  File "C:\Users\secondBrother\.virtualenvs\py\lib\site-packages\django\http\response.py", line 558, in __init__
    data = json.dumps(data, cls=encoder, **json_dumps_params)
  File "C:\Python36\lib\json\__init__.py", line 238, in dumps
    **kw).encode(obj)
  File "C:\Python36\lib\json\encoder.py", line 199, in encode
    chunks = self.iterencode(o, _one_shot=True)
  File "C:\Python36\lib\json\encoder.py", line 257, in iterencode
    return _iterencode(o, 0)
  File "C:\Users\secondBrother\.virtualenvs\py\lib\site-packages\django\core\serializers\json.py", line 104, in default
    return super().default(o)
  File "C:\Python36\lib\json\encoder.py", line 180, in default
    o.__class__.__name__)
TypeError: Object of type 'dict_values' is not JSON serializable
[ERROR] [2019-10-16 16:24:36,332] [basehttp] [136] "GET /api/interview_msg/?date=2019-10-16 HTTP/1.1" 500 115737
[ERROR] [2019-10-16 16:27:58,806] [log] [228] Internal Server Error: /api/interview_msg/
Traceback (most recent call last):
  File "C:\Users\secondBrother\.virtualenvs\py\lib\site-packages\django\core\handlers\exception.py", line 34, in inner
    response = get_response(request)
  File "C:\Users\secondBrother\.virtualenvs\py\lib\site-packages\django\core\handlers\base.py", line 126, in _get_response
    response = self.process_exception_by_middleware(e, request)
  File "C:\Users\secondBrother\.virtualenvs\py\lib\site-packages\django\core\handlers\base.py", line 124, in _get_response
    response = wrapped_callback(request, *callback_args, **callback_kwargs)
  File "C:\Users\secondBrother\.virtualenvs\py\lib\site-packages\django\views\generic\base.py", line 68, in view
    return self.dispatch(request, *args, **kwargs)
  File "C:\Users\secondBrother\.virtualenvs\py\lib\site-packages\django\views\generic\base.py", line 88, in dispatch
    return handler(request, *args, **kwargs)
  File "D:\project\yeslab-booking-systerm\backend\infos\views.py", line 47, in get
    return JsonResponse(data.values(), safe=False)
  File "C:\Users\secondBrother\.virtualenvs\py\lib\site-packages\django\http\response.py", line 558, in __init__
    data = json.dumps(data, cls=encoder, **json_dumps_params)
  File "C:\Python36\lib\json\__init__.py", line 238, in dumps
    **kw).encode(obj)
  File "C:\Python36\lib\json\encoder.py", line 199, in encode
    chunks = self.iterencode(o, _one_shot=True)
  File "C:\Python36\lib\json\encoder.py", line 257, in iterencode
    return _iterencode(o, 0)
  File "C:\Users\secondBrother\.virtualenvs\py\lib\site-packages\django\core\serializers\json.py", line 104, in default
    return super().default(o)
  File "C:\Python36\lib\json\encoder.py", line 180, in default
    o.__class__.__name__)
TypeError: Object of type 'dict_values' is not JSON serializable
[ERROR] [2019-10-16 16:27:58,810] [basehttp] [136] "GET /api/interview_msg/?date=2019-10-16 HTTP/1.1" 500 115746
[ERROR] [2019-10-16 16:48:32,590] [log] [228] Internal Server Error: /api/interview/
Traceback (most recent call last):
  File "C:\Users\secondBrother\.virtualenvs\py\lib\site-packages\django\core\handlers\exception.py", line 34, in inner
    response = get_response(request)
  File "C:\Users\secondBrother\.virtualenvs\py\lib\site-packages\django\core\handlers\base.py", line 126, in _get_response
    response = self.process_exception_by_middleware(e, request)
  File "C:\Users\secondBrother\.virtualenvs\py\lib\site-packages\django\core\handlers\base.py", line 124, in _get_response
    response = wrapped_callback(request, *callback_args, **callback_kwargs)
  File "C:\Users\secondBrother\.virtualenvs\py\lib\site-packages\django\views\generic\base.py", line 68, in view
    return self.dispatch(request, *args, **kwargs)
  File "C:\Users\secondBrother\.virtualenvs\py\lib\site-packages\django\views\generic\base.py", line 88, in dispatch
    return handler(request, *args, **kwargs)
  File "D:\project\yeslab-booking-systerm\backend\infos\views.py", line 47, in post
    i = InterviewInfo.objects.filter(date=date,tb_id=tb_id)[0]
  File "C:\Users\secondBrother\.virtualenvs\py\lib\site-packages\django\db\models\query.py", line 303, in __getitem__
    return qs._result_cache[0]
IndexError: list index out of range
[ERROR] [2019-10-16 16:48:32,593] [basehttp] [136] "POST /api/interview/ HTTP/1.1" 500 88612
[ERROR] [2019-10-16 17:13:33,418] [basehttp] [136] "GET /xadmin/infos/interviewinfo/ HTTP/1.1" 500 59
[ERROR] [2019-10-16 17:13:34,303] [basehttp] [136] "GET /xadmin/infos/interviewinfo/ HTTP/1.1" 500 59
[ERROR] [2019-10-16 17:14:03,568] [log] [228] Internal Server Error: /api/interview/
Traceback (most recent call last):
  File "C:\Users\secondBrother\.virtualenvs\py\lib\site-packages\django\core\handlers\exception.py", line 34, in inner
    response = get_response(request)
  File "C:\Users\secondBrother\.virtualenvs\py\lib\site-packages\django\core\handlers\base.py", line 126, in _get_response
    response = self.process_exception_by_middleware(e, request)
  File "C:\Users\secondBrother\.virtualenvs\py\lib\site-packages\django\core\handlers\base.py", line 124, in _get_response
    response = wrapped_callback(request, *callback_args, **callback_kwargs)
  File "C:\Users\secondBrother\.virtualenvs\py\lib\site-packages\django\views\generic\base.py", line 68, in view
    return self.dispatch(request, *args, **kwargs)
  File "C:\Users\secondBrother\.virtualenvs\py\lib\site-packages\django\utils\decorators.py", line 45, in _wrapper
    return bound_method(*args, **kwargs)
  File "D:\project\yeslab-booking-systerm\backend\users\views.py", line 30, in inner
    return func(request,*args,**kwargs)
  File "C:\Users\secondBrother\.virtualenvs\py\lib\site-packages\django\views\generic\base.py", line 88, in dispatch
    return handler(request, *args, **kwargs)
  File "D:\project\yeslab-booking-systerm\backend\infos\views.py", line 46, in post
    tb_id = tb_id if tb_id and re.match(r'^\d{1,2}$', tb_id) else ""
  File "C:\Python36\lib\re.py", line 172, in match
    return _compile(pattern, flags).match(string)
TypeError: expected string or bytes-like object
[ERROR] [2019-10-16 17:14:03,577] [basehttp] [136] "POST /api/interview/ HTTP/1.1" 500 98474
[ERROR] [2019-10-16 17:22:55,649] [log] [228] Internal Server Error: /api/interview/
Traceback (most recent call last):
  File "C:\Users\secondBrother\.virtualenvs\py\lib\site-packages\django\core\handlers\exception.py", line 34, in inner
    response = get_response(request)
  File "C:\Users\secondBrother\.virtualenvs\py\lib\site-packages\django\core\handlers\base.py", line 126, in _get_response
    response = self.process_exception_by_middleware(e, request)
  File "C:\Users\secondBrother\.virtualenvs\py\lib\site-packages\django\core\handlers\base.py", line 124, in _get_response
    response = wrapped_callback(request, *callback_args, **callback_kwargs)
  File "C:\Users\secondBrother\.virtualenvs\py\lib\site-packages\django\views\generic\base.py", line 68, in view
    return self.dispatch(request, *args, **kwargs)
  File "C:\Users\secondBrother\.virtualenvs\py\lib\site-packages\django\utils\decorators.py", line 45, in _wrapper
    return bound_method(*args, **kwargs)
  File "D:\project\yeslab-booking-systerm\backend\users\views.py", line 30, in inner
    return func(request,*args,**kwargs)
  File "C:\Users\secondBrother\.virtualenvs\py\lib\site-packages\django\views\generic\base.py", line 88, in dispatch
    return handler(request, *args, **kwargs)
  File "D:\project\yeslab-booking-systerm\backend\infos\views.py", line 47, in post
    tb_id = tb_id if tb_id and re.match(r'^\d{1,2}$', tb_id) else ""
  File "C:\Python36\lib\re.py", line 172, in match
    return _compile(pattern, flags).match(string)
TypeError: expected string or bytes-like object
[ERROR] [2019-10-16 17:22:55,652] [basehttp] [136] "POST /api/interview/ HTTP/1.1" 500 98474
[ERROR] [2019-10-16 17:24:37,168] [log] [228] Internal Server Error: /api/interview/
Traceback (most recent call last):
  File "C:\Users\secondBrother\.virtualenvs\py\lib\site-packages\django\core\handlers\exception.py", line 34, in inner
    response = get_response(request)
  File "C:\Users\secondBrother\.virtualenvs\py\lib\site-packages\django\core\handlers\base.py", line 126, in _get_response
    response = self.process_exception_by_middleware(e, request)
  File "C:\Users\secondBrother\.virtualenvs\py\lib\site-packages\django\core\handlers\base.py", line 124, in _get_response
    response = wrapped_callback(request, *callback_args, **callback_kwargs)
  File "C:\Users\secondBrother\.virtualenvs\py\lib\site-packages\django\views\generic\base.py", line 68, in view
    return self.dispatch(request, *args, **kwargs)
  File "C:\Users\secondBrother\.virtualenvs\py\lib\site-packages\django\utils\decorators.py", line 45, in _wrapper
    return bound_method(*args, **kwargs)
  File "D:\project\yeslab-booking-systerm\backend\users\views.py", line 30, in inner
    return func(request,*args,**kwargs)
  File "C:\Users\secondBrother\.virtualenvs\py\lib\site-packages\django\views\generic\base.py", line 88, in dispatch
    return handler(request, *args, **kwargs)
  File "D:\project\yeslab-booking-systerm\backend\infos\views.py", line 47, in post
    tb_id = tb_id if tb_id and re.match(r'^\d{1,2}$', tb_id) else ""
  File "C:\Python36\lib\re.py", line 172, in match
    return _compile(pattern, flags).match(string)
TypeError: expected string or bytes-like object
[ERROR] [2019-10-16 17:24:37,172] [basehttp] [136] "POST /api/interview/ HTTP/1.1" 500 98507
[ERROR] [2019-10-16 17:25:17,847] [log] [228] Internal Server Error: /api/interview/
Traceback (most recent call last):
  File "C:\Users\secondBrother\.virtualenvs\py\lib\site-packages\django\core\handlers\exception.py", line 34, in inner
    response = get_response(request)
  File "C:\Users\secondBrother\.virtualenvs\py\lib\site-packages\django\core\handlers\base.py", line 126, in _get_response
    response = self.process_exception_by_middleware(e, request)
  File "C:\Users\secondBrother\.virtualenvs\py\lib\site-packages\django\core\handlers\base.py", line 124, in _get_response
    response = wrapped_callback(request, *callback_args, **callback_kwargs)
  File "C:\Users\secondBrother\.virtualenvs\py\lib\site-packages\django\views\generic\base.py", line 68, in view
    return self.dispatch(request, *args, **kwargs)
  File "C:\Users\secondBrother\.virtualenvs\py\lib\site-packages\django\utils\decorators.py", line 45, in _wrapper
    return bound_method(*args, **kwargs)
  File "D:\project\yeslab-booking-systerm\backend\users\views.py", line 30, in inner
    return func(request,*args,**kwargs)
  File "C:\Users\secondBrother\.virtualenvs\py\lib\site-packages\django\views\generic\base.py", line 88, in dispatch
    return handler(request, *args, **kwargs)
  File "D:\project\yeslab-booking-systerm\backend\infos\views.py", line 47, in post
    tb_id = tb_id if tb_id and re.match(r'^\d{1,2}$', tb_id) else ""
  File "C:\Python36\lib\re.py", line 172, in match
    return _compile(pattern, flags).match(string)
TypeError: expected string or bytes-like object
[ERROR] [2019-10-16 17:25:17,850] [basehttp] [136] "POST /api/interview/ HTTP/1.1" 500 98519
[ERROR] [2019-10-16 17:26:39,162] [log] [228] Internal Server Error: /api/interview/
Traceback (most recent call last):
  File "C:\Users\secondBrother\.virtualenvs\py\lib\site-packages\django\core\handlers\exception.py", line 34, in inner
    response = get_response(request)
  File "C:\Users\secondBrother\.virtualenvs\py\lib\site-packages\django\core\handlers\base.py", line 126, in _get_response
    response = self.process_exception_by_middleware(e, request)
  File "C:\Users\secondBrother\.virtualenvs\py\lib\site-packages\django\core\handlers\base.py", line 124, in _get_response
    response = wrapped_callback(request, *callback_args, **callback_kwargs)
  File "C:\Users\secondBrother\.virtualenvs\py\lib\site-packages\django\views\generic\base.py", line 68, in view
    return self.dispatch(request, *args, **kwargs)
  File "C:\Users\secondBrother\.virtualenvs\py\lib\site-packages\django\utils\decorators.py", line 45, in _wrapper
    return bound_method(*args, **kwargs)
  File "D:\project\yeslab-booking-systerm\backend\users\views.py", line 30, in inner
    return func(request,*args,**kwargs)
  File "C:\Users\secondBrother\.virtualenvs\py\lib\site-packages\django\views\generic\base.py", line 88, in dispatch
    return handler(request, *args, **kwargs)
  File "D:\project\yeslab-booking-systerm\backend\infos\views.py", line 47, in post
    tb_id = tb_id if tb_id and re.match(r'^\d{1,2}$', tb_id) else ""
  File "C:\Python36\lib\re.py", line 172, in match
    return _compile(pattern, flags).match(string)
TypeError: expected string or bytes-like object
[ERROR] [2019-10-16 17:26:39,165] [basehttp] [136] "POST /api/interview/ HTTP/1.1" 500 98519
[ERROR] [2019-10-16 17:29:16,618] [log] [228] Internal Server Error: /api/interview/
Traceback (most recent call last):
  File "C:\Users\secondBrother\.virtualenvs\py\lib\site-packages\django\core\handlers\exception.py", line 34, in inner
    response = get_response(request)
  File "C:\Users\secondBrother\.virtualenvs\py\lib\site-packages\django\core\handlers\base.py", line 126, in _get_response
    response = self.process_exception_by_middleware(e, request)
  File "C:\Users\secondBrother\.virtualenvs\py\lib\site-packages\django\core\handlers\base.py", line 124, in _get_response
    response = wrapped_callback(request, *callback_args, **callback_kwargs)
  File "C:\Users\secondBrother\.virtualenvs\py\lib\site-packages\django\views\generic\base.py", line 68, in view
    return self.dispatch(request, *args, **kwargs)
  File "C:\Users\secondBrother\.virtualenvs\py\lib\site-packages\django\utils\decorators.py", line 45, in _wrapper
    return bound_method(*args, **kwargs)
  File "D:\project\yeslab-booking-systerm\backend\users\views.py", line 30, in inner
    return func(request,*args,**kwargs)
  File "C:\Users\secondBrother\.virtualenvs\py\lib\site-packages\django\views\generic\base.py", line 88, in dispatch
    return handler(request, *args, **kwargs)
  File "D:\project\yeslab-booking-systerm\backend\infos\views.py", line 50, in post
    if not all(date, tb_id, user_id):
TypeError: all() takes exactly one argument (3 given)
[ERROR] [2019-10-16 17:29:16,622] [basehttp] [136] "POST /api/interview/ HTTP/1.1" 500 94743
[ERROR] [2019-10-16 17:31:49,981] [views] [63] argument of type 'ManyRelatedManager' is not iterable
[ERROR] [2019-10-16 17:33:50,411] [views] [63] get() returned more than one InterviewInfo -- it returned 2!
[ERROR] [2019-10-16 17:37:29,014] [views] [63] get() returned more than one InterviewInfo -- it returned 2!
[ERROR] [2019-10-16 17:43:07,423] [log] [228] Internal Server Error: /api/myreservations/
Traceback (most recent call last):
  File "C:\Users\secondBrother\.virtualenvs\py\lib\site-packages\django\core\handlers\exception.py", line 34, in inner
    response = get_response(request)
  File "C:\Users\secondBrother\.virtualenvs\py\lib\site-packages\django\core\handlers\base.py", line 126, in _get_response
    response = self.process_exception_by_middleware(e, request)
  File "C:\Users\secondBrother\.virtualenvs\py\lib\site-packages\django\core\handlers\base.py", line 124, in _get_response
    response = wrapped_callback(request, *callback_args, **callback_kwargs)
  File "C:\Users\secondBrother\.virtualenvs\py\lib\site-packages\django\views\generic\base.py", line 68, in view
    return self.dispatch(request, *args, **kwargs)
  File "C:\Users\secondBrother\.virtualenvs\py\lib\site-packages\django\utils\decorators.py", line 45, in _wrapper
    return bound_method(*args, **kwargs)
  File "D:\project\yeslab-booking-systerm\backend\users\views.py", line 30, in inner
    return func(request,*args,**kwargs)
  File "C:\Users\secondBrother\.virtualenvs\py\lib\site-packages\django\views\generic\base.py", line 88, in dispatch
    return handler(request, *args, **kwargs)
  File "D:\project\yeslab-booking-systerm\backend\experiments\views.py", line 148, in post
    req_data = json.loads(json_str)
  File "C:\Python36\lib\json\__init__.py", line 354, in loads
    return _default_decoder.decode(s)
  File "C:\Python36\lib\json\decoder.py", line 339, in decode
    obj, end = self.raw_decode(s, idx=_w(s, 0).end())
  File "C:\Python36\lib\json\decoder.py", line 357, in raw_decode
    raise JSONDecodeError("Expecting value", s, err.value) from None
json.decoder.JSONDecodeError: Expecting value: line 1 column 1 (char 0)
[ERROR] [2019-10-16 17:43:07,429] [basehttp] [136] "POST /api/myreservations/ HTTP/1.1" 500 109606
[ERROR] [2019-10-16 17:50:11,508] [log] [228] Internal Server Error: /api/myreservations/
Traceback (most recent call last):
  File "C:\Users\secondBrother\.virtualenvs\py\lib\site-packages\django\core\handlers\exception.py", line 34, in inner
    response = get_response(request)
  File "C:\Users\secondBrother\.virtualenvs\py\lib\site-packages\django\core\handlers\base.py", line 126, in _get_response
    response = self.process_exception_by_middleware(e, request)
  File "C:\Users\secondBrother\.virtualenvs\py\lib\site-packages\django\core\handlers\base.py", line 124, in _get_response
    response = wrapped_callback(request, *callback_args, **callback_kwargs)
  File "C:\Users\secondBrother\.virtualenvs\py\lib\site-packages\django\views\generic\base.py", line 68, in view
    return self.dispatch(request, *args, **kwargs)
  File "C:\Users\secondBrother\.virtualenvs\py\lib\site-packages\django\utils\decorators.py", line 45, in _wrapper
    return bound_method(*args, **kwargs)
  File "D:\project\yeslab-booking-systerm\backend\users\views.py", line 30, in inner
    return func(request,*args,**kwargs)
  File "C:\Users\secondBrother\.virtualenvs\py\lib\site-packages\django\views\generic\base.py", line 88, in dispatch
    return handler(request, *args, **kwargs)
  File "D:\project\yeslab-booking-systerm\backend\experiments\views.py", line 148, in post
    req_data = json.loads(json_str)
  File "C:\Python36\lib\json\__init__.py", line 354, in loads
    return _default_decoder.decode(s)
  File "C:\Python36\lib\json\decoder.py", line 339, in decode
    obj, end = self.raw_decode(s, idx=_w(s, 0).end())
  File "C:\Python36\lib\json\decoder.py", line 357, in raw_decode
    raise JSONDecodeError("Expecting value", s, err.value) from None
json.decoder.JSONDecodeError: Expecting value: line 1 column 1 (char 0)
[ERROR] [2019-10-16 17:50:11,512] [basehttp] [136] "POST /api/myreservations/ HTTP/1.1" 500 109606
[ERROR] [2019-10-16 18:17:32,158] [log] [228] Internal Server Error: /api/myinterview/
Traceback (most recent call last):
  File "C:\Users\secondBrother\.virtualenvs\py\lib\site-packages\django\core\handlers\exception.py", line 34, in inner
    response = get_response(request)
  File "C:\Users\secondBrother\.virtualenvs\py\lib\site-packages\django\core\handlers\base.py", line 126, in _get_response
    response = self.process_exception_by_middleware(e, request)
  File "C:\Users\secondBrother\.virtualenvs\py\lib\site-packages\django\core\handlers\base.py", line 124, in _get_response
    response = wrapped_callback(request, *callback_args, **callback_kwargs)
  File "C:\Users\secondBrother\.virtualenvs\py\lib\site-packages\django\views\generic\base.py", line 68, in view
    return self.dispatch(request, *args, **kwargs)
  File "C:\Users\secondBrother\.virtualenvs\py\lib\site-packages\django\utils\decorators.py", line 45, in _wrapper
    return bound_method(*args, **kwargs)
  File "D:\project\yeslab-booking-systerm\backend\users\views.py", line 30, in inner
    return func(request,*args,**kwargs)
  File "C:\Users\secondBrother\.virtualenvs\py\lib\site-packages\django\views\generic\base.py", line 88, in dispatch
    return handler(request, *args, **kwargs)
  File "D:\project\yeslab-booking-systerm\backend\infos\views.py", line 95, in post
    tb_id = tb_id if tb_id and re.match(r'^\d{1,2}$', tb_id) else ""
  File "C:\Python36\lib\re.py", line 172, in match
    return _compile(pattern, flags).match(string)
TypeError: expected string or bytes-like object
[ERROR] [2019-10-16 18:17:32,161] [basehttp] [136] "POST /api/myinterview/ HTTP/1.1" 500 98035
